concurrent.futures.process._RemoteTraceback: 
"""
Traceback (most recent call last):
  File "/g/data/xl04/ka6418/miniconda/lib/python3.10/concurrent/futures/process.py", line 246, in _process_worker
    r = call_item.fn(*call_item.args, **call_item.kwargs)
  File "/g/data/xl04/ka6418/miniconda/lib/python3.10/concurrent/futures/process.py", line 205, in _process_chunk
    return [fn(*args) for args in chunk]
  File "/g/data/xl04/ka6418/miniconda/lib/python3.10/concurrent/futures/process.py", line 205, in <listcomp>
    return [fn(*args) for args in chunk]
  File "/g/data/xl04/ka6418/github/ausarg/nextflow/non-experimental/work/b0/2a0365192ded95aa18e10857ba3d36/.command.sh", line 48, in parse_fastq
    with gzip.open(fastq_file, 'rt') as f:
  File "/g/data/xl04/ka6418/miniconda/lib/python3.10/gzip.py", line 58, in open
    binary_file = GzipFile(filename, gz_mode, compresslevel)
  File "/g/data/xl04/ka6418/miniconda/lib/python3.10/gzip.py", line 174, in __init__
    fileobj = self.myfileobj = builtins.open(filename, mode or 'rb')
FileNotFoundError: [Errno 2] No such file or directory: 'HIC_R1_val_1.fq.gz PE_1_val_1.fq.gz'
"""

The above exception was the direct cause of the following exception:

Traceback (most recent call last):
  File "/g/data/xl04/ka6418/github/ausarg/nextflow/non-experimental/work/b0/2a0365192ded95aa18e10857ba3d36/.command.sh", line 145, in <module>
    main()
  File "/g/data/xl04/ka6418/github/ausarg/nextflow/non-experimental/work/b0/2a0365192ded95aa18e10857ba3d36/.command.sh", line 106, in main
    for result in executor.map(parse_fastq, fastq_files):
  File "/g/data/xl04/ka6418/miniconda/lib/python3.10/concurrent/futures/process.py", line 570, in _chain_from_iterable_of_lists
    for element in iterable:
  File "/g/data/xl04/ka6418/miniconda/lib/python3.10/concurrent/futures/_base.py", line 621, in result_iterator
    yield _result_or_cancel(fs.pop())
  File "/g/data/xl04/ka6418/miniconda/lib/python3.10/concurrent/futures/_base.py", line 319, in _result_or_cancel
    return fut.result(timeout)
  File "/g/data/xl04/ka6418/miniconda/lib/python3.10/concurrent/futures/_base.py", line 458, in result
    return self.__get_result()
  File "/g/data/xl04/ka6418/miniconda/lib/python3.10/concurrent/futures/_base.py", line 403, in __get_result
    raise self._exception
FileNotFoundError: [Errno 2] No such file or directory: 'HIC_R1_val_1.fq.gz PE_1_val_1.fq.gz'
